2025-04-25 13:18:29,092 - jira_api - ERROR - JSON parsing error in tasks.json: Expecting value: line 2 column 5 (char 21)
2025-04-25 13:24:44,099 - jira_api - ERROR - JSON parsing error in unknown_file: Expecting value: line 2 column 5 (char 21)
2025-04-25 13:24:44,099 - jira_api - ERROR - JSON parsing error in unknown_file: Expecting value: line 2 column 5 (char 21)
2025-04-25 13:28:37,331 - jira_api - ERROR - JSON parsing error in unknown_file:
Line 2, Column 5:
<<unable to read file>>
    ^
Error: Expecting value: line 2 column 5 (char 21)
2025-04-25 13:28:37,331 - jira_api - ERROR - JSON parsing error in unknown_file:
Line 2, Column 5:
<<unable to read file>>
    ^
Error: Expecting value: line 2 column 5 (char 21)
2025-04-25 13:32:25,291 - jira_api - ERROR - JSON parsing error in unknown_file:
Line 2, Column 5:
<<unable to read file>>
    ^
Error: Expecting value: line 2 column 5 (char 21)
2025-04-25 13:32:25,291 - jira_api - ERROR - JSON parsing error in unknown_file:
Line 2, Column 5:
<<unable to read file>>
    ^
Error: Expecting value: line 2 column 5 (char 21)
2025-04-25 13:44:40,061 - jira_api - ERROR - JSON parsing error in unknown_file:
Line 2, Column 5:
<<unable to read file>>
    ^
Error: Expecting value: line 2 column 5 (char 21)
2025-04-25 13:44:40,061 - jira_api - ERROR - JSON parsing error in unknown_file:
Line 2, Column 5:
<<unable to read file>>
    ^
Error: Expecting value: line 2 column 5 (char 21)
2025-04-25 14:38:41,016 - jira_api - ERROR - Error in create_handler.py at line 263:
Function: process_tasks_file
Code: self.validate_handler.validate_and_prepare_project(data)
Error: 'JiraValidateHandler' object has no attribute 'validate_and_prepare_project'
Traceback (most recent call last):
  File "/Users/dong-hoshin/dev/neunexus/jira_API/src/utils/error_handler.py", line 120, in wrapper
    return func(*args, **kwargs)
  File "/Users/dong-hoshin/dev/neunexus/jira_API/src/utils/create_handler.py", line 263, in process_tasks_file
    self.validate_handler.validate_and_prepare_project(data)
    ^^^^^^^^^^^^^^^^^^^^^^^^^^^^^^^^^^^^^^^^^^^^^^^^^^
AttributeError: 'JiraValidateHandler' object has no attribute 'validate_and_prepare_project'

2025-04-25 14:38:41,016 - jira_api - ERROR - Error in create_handler.py at line 263:
Function: process_tasks_file
Code: self.validate_handler.validate_and_prepare_project(data)
Error: 'JiraValidateHandler' object has no attribute 'validate_and_prepare_project'
Traceback (most recent call last):
  File "/Users/dong-hoshin/dev/neunexus/jira_API/src/utils/error_handler.py", line 120, in wrapper
    return func(*args, **kwargs)
  File "/Users/dong-hoshin/dev/neunexus/jira_API/src/utils/create_handler.py", line 263, in process_tasks_file
    self.validate_handler.validate_and_prepare_project(data)
    ^^^^^^^^^^^^^^^^^^^^^^^^^^^^^^^^^^^^^^^^^^^^^^^^^^
AttributeError: 'JiraValidateHandler' object has no attribute 'validate_and_prepare_project'

2025-04-25 15:35:44,616 - jira_api - ERROR - Error in combi_handler.py at line 25:
Function: _validate_and_create_fields
Code: if not self.validate_handler.validate_field("fixVersions"):
Error: 'JiraValidateHandler' object has no attribute 'validate_field'
Traceback (most recent call last):
  File "/Users/dong-hoshin/dev/neunexus/jira_API/src/utils/error_handler.py", line 120, in wrapper
    return func(*args, **kwargs)
  File "/Users/dong-hoshin/dev/neunexus/jira_API/src/utils/combi_handler.py", line 49, in validate_and_prepare_project
    self._validate_and_create_fields()
    ~~~~~~~~~~~~~~~~~~~~~~~~~~~~~~~~^^
  File "/Users/dong-hoshin/dev/neunexus/jira_API/src/utils/combi_handler.py", line 25, in _validate_and_create_fields
    if not self.validate_handler.validate_field("fixVersions"):
           ^^^^^^^^^^^^^^^^^^^^^^^^^^^^^^^^^^^^
AttributeError: 'JiraValidateHandler' object has no attribute 'validate_field'. Did you mean: 'validate_epic'?

2025-04-25 15:35:44,616 - jira_api - ERROR - Error in combi_handler.py at line 25:
Function: _validate_and_create_fields
Code: if not self.validate_handler.validate_field("fixVersions"):
Error: 'JiraValidateHandler' object has no attribute 'validate_field'
Traceback (most recent call last):
  File "/Users/dong-hoshin/dev/neunexus/jira_API/src/utils/error_handler.py", line 120, in wrapper
    return func(*args, **kwargs)
  File "/Users/dong-hoshin/dev/neunexus/jira_API/src/utils/combi_handler.py", line 49, in validate_and_prepare_project
    self._validate_and_create_fields()
    ~~~~~~~~~~~~~~~~~~~~~~~~~~~~~~~~^^
  File "/Users/dong-hoshin/dev/neunexus/jira_API/src/utils/combi_handler.py", line 25, in _validate_and_create_fields
    if not self.validate_handler.validate_field("fixVersions"):
           ^^^^^^^^^^^^^^^^^^^^^^^^^^^^^^^^^^^^
AttributeError: 'JiraValidateHandler' object has no attribute 'validate_field'. Did you mean: 'validate_epic'?

2025-04-25 17:59:44,462 - jira_api - ERROR - Error in create_handler.py at line 43:
Function: load_yaml_file
Code: with open(filepath, 'r', encoding='utf-8') as file:
Error: [Errno 2] No such file or directory: 'tasks.yaml'
Traceback (most recent call last):
  File "/Users/dong-hoshin/dev/neunexus/jira_API/src/utils/error_handler.py", line 120, in wrapper
    return func(*args, **kwargs)
  File "/Users/dong-hoshin/dev/neunexus/jira_API/src/utils/create_handler.py", line 330, in process_yaml_file
    data = self.load_yaml_file(yaml_file)
  File "/Users/dong-hoshin/dev/neunexus/jira_API/src/utils/create_handler.py", line 43, in load_yaml_file
    with open(filepath, 'r', encoding='utf-8') as file:
         ~~~~^^^^^^^^^^^^^^^^^^^^^^^^^^^^^^^^^
FileNotFoundError: [Errno 2] No such file or directory: 'tasks.yaml'

2025-04-25 18:00:01,461 - jira_api - ERROR - Error in create_handler.py at line 43:
Function: load_yaml_file
Code: with open(filepath, 'r', encoding='utf-8') as file:
Error: [Errno 2] No such file or directory: '../../data/tasks.yaml'
Traceback (most recent call last):
  File "/Users/dong-hoshin/dev/neunexus/jira_API/src/utils/error_handler.py", line 120, in wrapper
    return func(*args, **kwargs)
  File "/Users/dong-hoshin/dev/neunexus/jira_API/src/utils/create_handler.py", line 330, in process_yaml_file
    data = self.load_yaml_file(yaml_file)
  File "/Users/dong-hoshin/dev/neunexus/jira_API/src/utils/create_handler.py", line 43, in load_yaml_file
    with open(filepath, 'r', encoding='utf-8') as file:
         ~~~~^^^^^^^^^^^^^^^^^^^^^^^^^^^^^^^^^
FileNotFoundError: [Errno 2] No such file or directory: '../../data/tasks.yaml'

2025-04-25 18:00:25,579 - jira_api - ERROR - Error in create_handler.py at line 43:
Function: load_yaml_file
Code: with open(filepath, 'r', encoding='utf-8') as file:
Error: [Errno 2] No such file or directory: '../../data/tasks.yaml'
Traceback (most recent call last):
  File "/Users/dong-hoshin/dev/neunexus/jira_API/src/utils/error_handler.py", line 120, in wrapper
    return func(*args, **kwargs)
  File "/Users/dong-hoshin/dev/neunexus/jira_API/src/utils/create_handler.py", line 330, in process_yaml_file
    data = self.load_yaml_file(yaml_file)
  File "/Users/dong-hoshin/dev/neunexus/jira_API/src/utils/create_handler.py", line 43, in load_yaml_file
    with open(filepath, 'r', encoding='utf-8') as file:
         ~~~~^^^^^^^^^^^^^^^^^^^^^^^^^^^^^^^^^
FileNotFoundError: [Errno 2] No such file or directory: '../../data/tasks.yaml'

2025-04-25 18:01:39,073 - jira_api - ERROR - Error in create_handler.py at line 43:
Function: load_yaml_file
Code: with open(filepath, 'r', encoding='utf-8') as file:
Error: [Errno 2] No such file or directory: '../../data/tasks.yaml'
Traceback (most recent call last):
  File "/Users/dong-hoshin/dev/neunexus/jira_API/src/utils/error_handler.py", line 120, in wrapper
    return func(*args, **kwargs)
  File "/Users/dong-hoshin/dev/neunexus/jira_API/src/utils/create_handler.py", line 330, in process_yaml_file
    data = self.load_yaml_file(yaml_file)
  File "/Users/dong-hoshin/dev/neunexus/jira_API/src/utils/create_handler.py", line 43, in load_yaml_file
    with open(filepath, 'r', encoding='utf-8') as file:
         ~~~~^^^^^^^^^^^^^^^^^^^^^^^^^^^^^^^^^
FileNotFoundError: [Errno 2] No such file or directory: '../../data/tasks.yaml'

2025-04-25 18:04:46,839 - jira_api - ERROR - Error in connect_handler.py at line 56:
Function: _make_request
Code: f"Invalid request: {error_details.get('errorMessages', ['Unknown error'])[0]}",
Error: list index out of range
Traceback (most recent call last):
  File "/Users/dong-hoshin/dev/neunexus/jira_API/src/utils/error_handler.py", line 120, in wrapper
    return func(*args, **kwargs)
  File "/Users/dong-hoshin/dev/neunexus/jira_API/src/utils/create_handler.py", line 192, in create_epic
    response = self.connect_handler._make_request("POST", "issue", json=payload)
  File "/Users/dong-hoshin/dev/neunexus/jira_API/src/utils/connect_handler.py", line 56, in _make_request
    f"Invalid request: {error_details.get('errorMessages', ['Unknown error'])[0]}",
                        ~~~~~~~~~~~~~~~~~~~~~~~~~~~~~~~~~~~~~~~~~~~~~~~~~~~~~^^^
IndexError: list index out of range

2025-04-25 18:10:10,379 - jira_api - ERROR - Error in connect_handler.py at line 60:
Function: _make_request
Code: f"Invalid request: {error_details.get('errorMessages', ['Unknown error'])[0]}",
Error: list index out of range
Traceback (most recent call last):
  File "/Users/dong-hoshin/dev/neunexus/jira_API/src/utils/error_handler.py", line 120, in wrapper
    return func(*args, **kwargs)
  File "/Users/dong-hoshin/dev/neunexus/jira_API/src/utils/create_handler.py", line 192, in create_epic
    response = self.connect_handler._make_request("POST", "issue", json=payload)
  File "/Users/dong-hoshin/dev/neunexus/jira_API/src/utils/connect_handler.py", line 60, in _make_request
    f"Invalid request: {error_details.get('errorMessages', ['Unknown error'])[0]}",
                        ~~~~~~~~~~~~~~~~~~~~~~~~~~~~~~~~~~~~~~~~~~~~~~~~~~~~~^^^
IndexError: list index out of range

2025-04-25 18:14:19,992 - jira_api - ERROR - Error in connect_handler.py at line 60:
Function: _make_request
Code: f"Invalid request: {error_details.get('errorMessages', ['Unknown error'])[0]}",
Error: list index out of range
Traceback (most recent call last):
  File "/Users/dong-hoshin/dev/neunexus/jira_API/src/utils/error_handler.py", line 120, in wrapper
    return func(*args, **kwargs)
  File "/Users/dong-hoshin/dev/neunexus/jira_API/src/utils/create_handler.py", line 192, in create_epic
    response = self.connect_handler._make_request("POST", "issue", json=payload)
  File "/Users/dong-hoshin/dev/neunexus/jira_API/src/utils/connect_handler.py", line 60, in _make_request
    f"Invalid request: {error_details.get('errorMessages', ['Unknown error'])[0]}",
                        ~~~~~~~~~~~~~~~~~~~~~~~~~~~~~~~~~~~~~~~~~~~~~~~~~~~~~^^^
IndexError: list index out of range

2025-04-25 18:25:42,780 - jira_api - ERROR - Error in connect_handler.py at line 60:
Function: _make_request
Code: f"Invalid request: {error_details.get('errorMessages', ['Unknown error'])[0]}",
Error: list index out of range
Traceback (most recent call last):
  File "/Users/dong-hoshin/dev/neunexus/jira_API/src/utils/error_handler.py", line 120, in wrapper
    return func(*args, **kwargs)
  File "/Users/dong-hoshin/dev/neunexus/jira_API/src/utils/create_handler.py", line 297, in create_task
    response = self.connect_handler._make_request("POST", "issue", json=payload)
  File "/Users/dong-hoshin/dev/neunexus/jira_API/src/utils/connect_handler.py", line 60, in _make_request
    f"Invalid request: {error_details.get('errorMessages', ['Unknown error'])[0]}",
                        ~~~~~~~~~~~~~~~~~~~~~~~~~~~~~~~~~~~~~~~~~~~~~~~~~~~~~^^^
IndexError: list index out of range

2025-04-25 18:43:38,696 - jira_api - ERROR - Error in connect_handler.py at line 60:
Function: _make_request
Code: f"Invalid request: {error_details.get('errorMessages', ['Unknown error'])[0]}",
Error: list index out of range
Traceback (most recent call last):
  File "/Users/dong-hoshin/dev/neunexus/jira_API/src/utils/error_handler.py", line 120, in wrapper
    return func(*args, **kwargs)
  File "/Users/dong-hoshin/dev/neunexus/jira_API/src/utils/create_handler.py", line 283, in create_hierarchical_task
    response = self.connect_handler._make_request("POST", "issue", json=payload)
  File "/Users/dong-hoshin/dev/neunexus/jira_API/src/utils/connect_handler.py", line 60, in _make_request
    f"Invalid request: {error_details.get('errorMessages', ['Unknown error'])[0]}",
                        ~~~~~~~~~~~~~~~~~~~~~~~~~~~~~~~~~~~~~~~~~~~~~~~~~~~~~^^^
IndexError: list index out of range

